<?xml version="1.0" encoding="utf-8"?>
<!-- This URDF was automatically created by SolidWorks to URDF Exporter! Originally created by Stephen Brawner (brawner@gmail.com) 
     Commit Version: 1.5.1-0-g916b5db  Build Version: 1.5.7152.31018
     For more information, please see http://wiki.ros.org/sw_urdf_exporter -->
<robot
  name="car">
  <link
    name="base_link">
    <inertial>
      <origin
        xyz="0.06882 0.017196 -0.0068298"
        rpy="0 0 0" />
      <mass
        value="0.05" />
      <inertia
        ixx="4.3083E-05"
        ixy="1.5102E-22"
        ixz="7.0549E-22"
        iyy="4.98E-05"
        iyz="-3.0611E-22"
        izz="8.7932E-06" />
    </inertial>
    <visual>
      <origin
        xyz="0 0 0"
        rpy="0 0 0" />
      <geometry>
        <mesh
          filename="package://car/meshes/base_link.STL" />
      </geometry>
      <material
        name="">
        <color
          rgba="0.79216 0.81961 0.93333 1" />
      </material>
    </visual>
    <collision>
      <origin
        xyz="0 0 0"
        rpy="0 0 0" />
      <geometry>
        <mesh
          filename="package://car/meshes/base_link.STL" />
      </geometry>
    </collision>
  </link>
  <link
    name="front_link">
    <inertial>
      <origin
        xyz="6.9389E-18 -3.4694E-18 0.005"
        rpy="0 0 0" />
      <mass
        value="0.005" />
      <inertia
        ixx="2.3265E-07"
        ixy="2.647E-23"
        ixz="3.9057E-23"
        iyy="2.3265E-07"
        iyz="-3.7293E-23"
        izz="3.835E-07" />
    </inertial>
    <visual>
      <origin
        xyz="0 0 0"
        rpy="0 0 0" />
      <geometry>
        <mesh
          filename="package://car/meshes/front_link.STL" />
      </geometry>
      <material
        name="">
        <color
          rgba="0.79216 0.81961 0.93333 1" />
      </material>
    </visual>
    <collision>
      <origin
        xyz="0 0 0"
        rpy="0 0 0" />
      <geometry>
        <mesh
          filename="package://car/meshes/front_link.STL" />
      </geometry>
    </collision>
  </link>
  <joint
    name="front"
    type="continuous">
    <origin
      xyz="0.06382 0.044613 0.017196"
      rpy="1.5708 -0.68485 1.5708" />
    <parent
      link="base_link" />
    <child
      link="front_link" />
    <axis
      xyz="0 0 1" />
  </joint>
  <link
    name="left_link">
    <inertial>
      <origin
        xyz="-6.9389E-18 -3.4694E-18 0.005"
        rpy="0 0 0" />
      <mass
        value="0.005" />
      <inertia
        ixx="2.3265E-07"
        ixy="6.6174E-24"
        ixz="4.2935E-23"
        iyy="2.3265E-07"
        iyz="-3.2172E-23"
        izz="3.835E-07" />
    </inertial>
    <visual>
      <origin
        xyz="0 0 0"
        rpy="0 0 0" />
      <geometry>
        <mesh
          filename="package://car/meshes/left_link.STL" />
      </geometry>
      <material
        name="">
        <color
          rgba="0.79216 0.81961 0.93333 1" />
      </material>
    </visual>
    <collision>
      <origin
        xyz="0 0 0"
        rpy="0 0 0" />
      <geometry>
        <mesh
          filename="package://car/meshes/left_link.STL" />
      </geometry>
    </collision>
  </link>
  <joint
    name="left"
    type="continuous">
    <origin
      xyz="0.03882 -0.025387 0.017196"
      rpy="1.5708 -0.68947 1.5708" />
    <parent
      link="base_link" />
    <child
      link="left_link" />
    <axis
      xyz="0 0 1" />
  </joint>
  <link
    name="right_link">
    <inertial>
      <origin
        xyz="5.2042E-18 3.1225E-17 0.005"
        rpy="0 0 0" />
      <mass
        value="0.005" />
      <inertia
        ixx="2.3265E-07"
        ixy="2.647E-23"
        ixz="2.3385E-22"
        iyy="2.3265E-07"
        iyz="1.6433E-22"
        izz="3.835E-07" />
    </inertial>
    <visual>
      <origin
        xyz="0 0 0"
        rpy="0 0 0" />
      <geometry>
        <mesh
          filename="package://car/meshes/right_link.STL" />
      </geometry>
      <material
        name="">
        <color
          rgba="0.79216 0.81961 0.93333 1" />
      </material>
    </visual>
    <collision>
      <origin
        xyz="0 0 0"
        rpy="0 0 0" />
      <geometry>
        <mesh
          filename="package://car/meshes/right_link.STL" />
      </geometry>
    </collision>
  </link>
  <joint
    name="right"
    type="continuous">
    <origin
      xyz="0.08882 -0.025387 0.017196"
      rpy="1.5708 -1.0266 1.5708" />
    <parent
      link="base_link" />
    <child
      link="right_link" />
    <axis
      xyz="0 0 1" />
  </joint>
</robot>